Workbook

Sheet Defict_dataframe
A1: Código Município Completo | B1: Nome_Município | C1: Sigla_UF | D1: Nome_Regiao | E1: MATOPIBA | F1: Latitude | G1: Longitude | H1: quantidade_produzida | I1: area_colhida | J1: valor_producao | K1: qtd_capacidade_estatica(t) | L1: defict_armazenagem
A2: 1100015 | B2: Alta Floresta D'Oeste | C2: RO | D2: Norte | E2: 0 | F2: -3.3483725 | G2: -64.70842 | H2: =IFERROR(VLOOKUP($A2,id_municipio_qtd_prod!$A:$E,3,0),0) -> 14373 | I2: =IFERROR(VLOOKUP($A2,id_municipio_qtd_prod!$A:$E,4,0),0) -> 3546 | J2: =IFERROR(VLOOKUP($A2,id_municipio_qtd_prod!$A:$E,5,0),0) -> 17876000 | K2: =IFERROR(VLOOKUP(A2,Id_municipio_cap_amzg!$A$1:$C$1466,3,0),0) -> 0 | L2: =K2-H2 -> -14373
A3: 1100379 | B3: Alto Alegre dos Parecis | C3: RO | D3: Norte | E3: 0 | F3: 3.8829783 | G3: -59.635206 | H3: =IFERROR(VLOOKUP($A3,id_municipio_qtd_prod!$A:$E,3,0),0) -> 25758 | I3: =IFERROR(VLOOKUP($A3,id_municipio_qtd_prod!$A:$E,4,0),0) -> 6451 | J3: =IFERROR(VLOOKUP($A3,id_municipio_qtd_prod!$A:$E,5,0),0) -> 32540000 | K3: =IFERROR(VLOOKUP(A3,Id_municipio_cap_amzg!$A$1:$C$1466,3,0),0) -> 11360 | L3: =K3-H3 -> -14398
A4: 1100403 | B4: Alto Paraíso | C4: RO | D4: Norte | E4: 0 | F4: -1.5273388 | G4: -52.576835 | H4: 154431 | I4: 41566 | J4: 228315000 | K4: 2160 | L4: =K4-H4 -> -152271
A5: 1100346 | B5: Alvorada D'Oeste | C5: RO | D5: Norte | E5: 0 | F5: -6.5321966 | G5: -49.848958 | H5: 3500 | I5: 1058 | J5: 5816000 | K5: 0 | L5: =K5-H5 -> -3500
A6: 1100023 | B6: Ariquemes | C6: RO | D6: Norte | E6: 0 | F6: -9.7988804 | G6: -49.651034 | H6: 87623 | I6: 23855 | J6: 123258000 | K6: 30630 | L6: =K6-H6 -> -56993
A7: 1100452 | B7: Buritis | C7: RO | D7: Norte | E7: 0 | F7: -7.7755629 | G7: -42.256958 | H7: 12467 | I7: 3412 | J7: 15848000 | K7: 0 | L7: =K7-H7 -> -12467
A8: 1100031 | B8: Cabixi | C8: RO | D8: Norte | E8: 0 | F8: -7.0813739 | G8: -41.468827 | H8: 214234 | I8: 53392 | J8: 275572000 | K8: 4180 | L8: =K8-H8 -> -210054
A9: 1100601 | B9: Cacaulândia | C9: RO | D9: Norte | E9: 0 | F9: -6.240183 | G9: -42.685024 | H9: 4474 | I9: 1105 | J9: 5367000 | K9: 0 | L9: =K9-H9 -> -4474
A10: 1100049 | B10: Cacoal | C10: RO | D10: Norte | E10: 0 | F10: -7.4930088 | G10: -42.570179 | H10: 36884 | I10: 9556 | J10: 50543000 | K10: 31750 | L10: =K10-H10 -> -5134
A11: 1100700 | B11: Campo Novo de Rondônia | C11: RO | D11: Norte | E11: 0 | F11: -5.6108896 | G11: -38.762526 | H11: 4726 | I11: 1334 | J11: 7101000 | K11: 0 | L11: =K11-H11 -> -4726
A12: 1100809 | B12: Candeias do Jamari | C12: RO | D12: Norte | E12: 0 | F12: -4.4850665 | G12: -38.598538 | H12: 153128 | I12: 40524 | J12: 216872000 | K12: 6010 | L12: =K12-H12 -> -147118
A13: 1100908 | B13: Castanheiras | C13: RO | D13: Norte | E13: 0 | F13: -5.2715587 | G13: -35.384872 | H13: 42330 | I13: 9615 | J13: 56454000 | K13: 0 | L13: =K13-H13 -> -42330
A14: 1100056 | B14: Cerejeiras | C14: RO | D14: Norte | E14: 0 | F14: -5.7781878 | G14: -37.956581 | H14: 263686 | I14: 66480 | J14: 329158000 | K14: 67160 | L14: =K14-H14 -> -196526
A15: 1100924 | B15: Chupinguaia | C15: RO | D15: Norte | E15: 0 | F15: -6.6940426 | G15: -35.536274 | H15: 340155 | I15: 72769 | J15: 398523000 | K15: 78070 | L15: =K15-H15 -> -262085
... A5566: 5300108 | B5566: Brasília | C5566: DF | D5566: Centro-Oeste | E5566: 0 | F5566: -7.1584176 | G5566: -41.35758 | H5566: 712723 | I5566: 160700 | J5566: 891976000 | K5566: 349721 | L5566: =K5566-H5566 -> -363002

Sheet id_municipio_qtd_prod
C3: Values | K3: Values
A4: id_municipio | B4: id_municipio_nome | C4: Sum of quantidade_produzida(t) | D4: Sum of area_colhida(he) | E4: Sum of valor_producao (R$) | H4: id_municipio | I4: id_municipio_nome | J4: produto | K4: Sum of quantidade_produzida(t) | L4: Sum of area_colhida(he) | M4: Sum of valor_producao (R$)
A5: 1100015 | B5: Alta Floresta D'Oeste | C5: 14373 | D5: 3546 | E5: 17876000 | H5: 5107925 | I5: Sorriso | J5: Milho (em grão) | K5: 3660000 | L5: 500000 | M5: 2361908000
A6: 1100023 | B6: Ariquemes | C6: 87623 | D6: 23855 | E6: 123258000 | J6: Soja (em grão) | K6: 2084520 | L6: 599000 | M6: 3331063000
A7: 1100031 | B7: Cabixi | C7: 214234 | D7: 53392 | E7: 275572000 | H7: Grand Total | K7: 5744520 | L7: 1099000 | M7: 5692971000
A8: 1100049 | B8: Cacoal | C8: 36884 | D8: 9556 | E8: 50543000
A9: 1100056 | B9: Cerejeiras | C9: 263686 | D9: 66480 | E9: 329158000
A10: 1100064 | B10: Colorado do Oeste | C10: 16544 | D10: 4185 | E10: 19601000
A11: 1100072 | B11: Corumbiara | C11: 361811 | D11: 85763 | E11: 432220000
A12: 1100080 | B12: Costa Marques | C12: 44773 | D12: 11264 | E12: 56323000
A13: 1100098 | B13: Espigão D'Oeste | C13: 12200 | D13: 3296 | E13: 16017000
A14: 1100106 | B14: Guajará-Mirim | C14: 42875 | D14: 11725 | E14: 62903000
A15: 1100114 | B15: Jaru | C15: 2376 | D15: 637 | E15: 2547000
A16: 1100122 | B16: Ji-Paraná | C16: 2528 | D16: 623 | E16: 2340000
A17: 1100130 | B17: Machadinho D'Oeste | C17: 88471 | D17: 22925 | E17: 119101000
A18: 1100148 | B18: Nova Brasilândia D'Oeste | C18: 12161 | D18: 3074 | E18: 16375000
A19: 1100155 | B19: Ouro Preto do Oeste | C19: 13300 | D19: 3231 | E19: 16304000
... A1134: 2410207 | B1134: Portalegre | C1134: 44 | D1134: 45 | E1134: 74000
A1135: 2410256 | B1135: Porto do Mangue | C1135: 0 | E1135: 0
A1136: 2410306 | B1136: Serra Caiada | C1136: 30 | D1136: 80 | E1136: 38000
A1137: 2410405 | B1137: Pureza | C1137: 80 | D1137: 100 | E1137: 136000
A1138: 2410504 | B1138: Rafael Fernandes | C1138: 93 | D1138: 280 | E1138: 186000
A1139: 2410603 | B1139: Rafael Godeiro | C1139: 20 | D1139: 125 | E1139: 27000
A1140: 2410702 | B1140: Riacho da Cruz | C1140: 74 | D1140: 140 | E1140: 99000
A1141: 2410801 | B1141: Riacho de Santana | C1141: 27 | D1141: 60 | E1141: 45000
A1142: 2410900 | B1142: Riachuelo | C1142: 232 | D1142: 60 | E1142: 232000
A1143: 2411007 | B1143: Rodolfo Fernandes | C1143: 19 | D1143: 75 | E1143: 28000
A1144: 2411056 | B1144: Tibau | C1144: 62 | D1144: 154 | E1144: 68000
A1145: 2411106 | B1145: Ruy Barbosa | C1145: 45 | D1145: 90 | E1145: 90000
A1146: 2411205 | B1146: Santa Cruz | C1146: 72 | D1146: 1200 | E1146: 140000
A1147: 2411403 | B1147: Santana do Matos | C1147: 25 | D1147: 60 | E1147: 43000
... A1720: 2903508 | B1720: Belo Campo | C1720: 750 | D1720: 500 | E1720: 760000
A1721: 2903607 | B1721: Biritinga | C1721: 0 | E1721: 0
A1722: 2903805 | B1722: Boa Vista do Tupim | C1722: 337 | D1722: 312 | E1722: 328000
A1723: 2903904 | B1723: Bom Jesus da Lapa | C1723: 407 | D1723: 981 | E1723: 344000
A1724: 2903953 | B1724: Bom Jesus da Serra | C1724: 60 | D1724: 402 | E1724: 67000
A1725: 2904001 | B1725: Boninal | C1725: 21 | D1725: 500 | E1725: 26000
A1726: 2904050 | B1726: Bonito | C1726: 178 | D1726: 41 | E1726: 174000
A1727: 2904100 | B1727: Boquira | C1727: 151 | D1727: 765 | E1727: 180000
A1728: 2904209 | B1728: Botuporã | C1728: 387 | D1728: 418 | E1728: 346000
...

Sheet Dataframe_pam
A1: ano | B1: id_municipio | C1: id_municipio_nome | D1: produto | E1: area_plantada(he) | F1: area_colhida(he) | G1: quantidade_produzida(t) | H1: rendimento_medio_producao | I1: valor_producao (R$)
A2: 2024 | B2: 5003157 | C2: Coronel Sapucaia | D2: Sorgo (em grão) | E2: 1700 | F2: 1700 | G2: 3400 | H2: 20000 | I2: 1700000
A3: 2024 | B3: 1100379 | C3: Alto Alegre dos Parecis | D3: Soja (em grão) | E3: 3579 | F3: 3579 | G3: 13099 | H3: 36600 | I3: 21218000
A4: 2024 | B4: 1200013 | C4: Acrelândia | D4: Soja (em grão) | E4: 25 | F4: 25 | G4: 93 | H4: 37200 | I4: 170000
A5: 2024 | B5: 2203008 | C5: Cristalândia do Piauí | D5: Soja (em grão) | E5: 1562 | F5: 1562 | G5: 6092 | H5: 39000 | I5: 11829000
A6: 2024 | B6: 2703759 | C6: Jequiá da Praia | D6: Soja (em grão) | E6: 495 | F6: 495 | G6: 1832 | H6: 37010 | I6: 3664000
A7: 2024 | B7: 3134806 | C7: Jacuí | D7: Soja (em grão) | E7: 2300 | F7: 2300 | G7: 8280 | H7: 36000 | I7: 15070000
A8: 2024 | B8: 3519055 | C8: Holambra | D8: Soja (em grão) | E8: 730 | F8: 730 | G8: 3066 | H8: 42000 | I8: 6077000
A9: 2024 | B9: 3519709 | C9: Ibiúna | D9: Soja (em grão) | E9: 290 | F9: 290 | G9: 870 | H9: 30000 | I9: 1697000
A10: 2024 | B10: 3527702 | C10: Luiziânia | D10: Soja (em grão) | E10: 180 | F10: 180 | G10: 540 | H10: 30000 | I10: 978000
A11: 2024 | B11: 4116703 | C11: Nova Aurora | D11: Soja (em grão) | E11: 34190 | F11: 34190 | G11: 122913 | H11: 35950 | I11: 216278000
A12: 2024 | B12: 4120408 | C12: Presidente Castelo Branco | D12: Soja (em grão) | E12: 3100 | F12: 3100 | G12: 7688 | H12: 24800 | I12: 13535000
A13: 2024 | B13: 4207601 | C13: Ipira | D13: Soja (em grão) | E13: 340 | F13: 340 | G13: 1224 | H13: 36000 | I13: 2509000
... A48: 2024 | B48: 5212600 | C48: Mairipotaba | D48: Girassol (em grão) | E48: 110 | F48: 110 | G48: 176 | H48: 16000 | I48: 334000
A49: 2024 | B49: 3552700 | C49: Tabatinga | D49: Sorgo (em grão) | E49: 35 | G49: 0 | I49: 0
A50: 2024 | B50: 5001003 | C50: Aparecida do Taboado | D50: Sorgo (em grão) | E50: 242 | F50: 242 | G50: 1278 | H50: 52810 | I50: 959000
A51: 2024 | B51: 5003702 | C51: Dourados | D51: Sorgo (em grão) | E51: 1425 | F51: 1425 | G51: 2565 | H51: 18000 | I51: 1283000
A52: 2024 | B52: 1100023 | C52: Ariquemes | D52: Soja (em grão) | E52: 15980 | F52: 15980 | G52: 52734 | H52: 33000 | I52: 93540000
A53: 2024 | B53: 1400209 | C53: Caracaraí | D53: Soja (em grão) | E53: 685 | F53: 685 | G53: 2466 | H53: 36000 | I53: 5137000
A54: 2024 | B54: 2100105 | C54: Afonso Cunha | D54: Soja (em grão) | E54: 8030 | F54: 8030 | G54: 24090 | H54: 30000 | I54: 53981000
A55: 2024 | B55: 3102803 | C55: Andrelândia | D55: Soja (em grão) | E55: 1600 | F55: 1600 | G55: 5568 | H55: 34800 | I55: 9883000
A56: 2024 | B56: 3133758 | C56: Itaú de Minas | D56: Soja (em grão) | E56: 750 | F56: 750 | G56: 2700 | H56: 36000 | I56: 4700000
A57: 2024 | B57: 3527108 | C57: Lins | D57: Soja (em grão) | E57: 726 | F57: 726 | G57: 1982 | H57: 27300 | I57: 3469000
A58: 2024 | B58: 4109807 | C58: Ibiporã | D58: Soja (em grão) | E58: 16400 | F58: 16400 | G58: 60680 | H58: 37000 | I58: 115292000
A59: 2024 | B59: 4114906 | C59: Marilândia do Sul | D59: Soja (em grão) | E59: 22550 | F59: 22550 | G59: 78925 | H59: 35000 | I59: 154693000
A60: 2024 | B60: 4219309 | C60: Videira | D60: Soja (em grão) | E60: 2300 | F60: 2300 | G60: 8034 | H60: 34930 | I60: 16068000
A61: 2024 | B61: 4315800 | C61: Roca Sales | D61: Soja (em grão) | E61: 1950 | F61: 1370 | G61: 4110 | H61: 30000 | I61: 7945000
... A2187: 2024 | B2187: 4124707 | C2187: São Jerônimo da Serra | D2187: Sorgo (em grão) | E2187: 20 | F2187: 20 | G2187: 50 | H2187: 25000 | I2187: 30000
A2188: 2024 | B2188: 5007802 | C2188: Selvíria | D2188: Sorgo (em grão) | E2188: 20 | G2188: 0 | I2188: 0
A2189: 2024 | B2189: 3513900 | C2189: Divinolândia | D2189: Soja (em grão) | E2189: 20 | F2189: 20 | G2189: 72 | H2189: 36000 | I2189: 158000
A2190: 2024 | B2190: 3507001 | C2190: Boituva | D2190: Sorgo (em grão) | E2190: 20 | F2190: 20 | G2190: 90 | H2190: 45000 | I2190: 63000
A2191: 2024 | B2191: 4209508 | C2191: Laurentino | D2191: Soja (em grão) | E2191: 20 | F2191: 20 | G2191: 60 | H2191: 30000 | I2191: 126000
A2192: 2024 | B2192: 3539509 | C2192: Pitangueiras | D2192: Sorgo (em grão) | E2192: 20 | F2192: 20 | G2192: 60 | H2192: 30000 | I2192: 44000
A2193: 2024 | B2193: 3524303 | C2193: Jaboticabal | D2193: Sorgo (em grão) | E2193: 30 | F2193: 30 | G2193: 90 | H2193: 30000 | I2193: 67000
A2194: 2024 | B2194: 4101408 | C2194: Apucarana | D2194: Sorgo (em grão) | E2194: 30 | F2194: 30 | G2194: 96 | H2194: 32000 | I2194: 72000
A2195: 2024 | B2195: 4212403 | C2195: Pedras Grandes | D2195: Soja (em grão) | E2195: 30 | F2195: 30 | G2195: 105 | H2195: 35000 | I2195: 273000
A2196: 2024 | B2196: 3135902 | C2196: Jesuânia | D2196: Soja (em grão) | E2196: 30 | F2196: 30 | G2196: 90 | H2196: 30000 | I2196: 156000
A2197: 2024 | B2197: 3540259 | C2197: Pontalinda | D2197: Soja (em grão) | E2197: 30 | F2197: 30 | G2197: 90 | H2197: 30000 | I2197: 179000
A2198: 2024 | B2198: 3135050 | C2198: Jaíba | D2198: Sorgo (em grão) | E2198: 30 | F2198: 30 | G2198: 30 | H2198: 10000 | I2198: 20000
A2199: 2024 | B2199: 3103504 | C2199: Araguari | D2199: Girassol (em grão) | E2199: 30 | F2199: 30 | G2199: 45 | H2199: 15000 | I2199: 96000
...

Sheet Id_municipio_cap_amzg
A1: cod_ibge | B1: nom_municipio | C1: qtd_capacidade_estatica(t)
A2: 1100023 | B2: ARIQUEMES-RO | C2: 30630
A3: 1100031 | B3: CABIXI-RO | C3: 4180
A4: 1100049 | B4: CACOAL-RO | C4: 31750
A5: 1100056 | B5: CEREJEIRAS-RO | C5: 67160
A6: 1100064 | B6: COLORADO DO OESTE-RO | C6: 12930
A7: 1100072 | B7: CORUMBIARA-RO | C7: 83460
A8: 1100098 | B8: ESPIGÃO D'OESTE-RO | C8: 3019
A9: 1100122 | B9: JI-PARANÁ-RO | C9: 89493
A10: 1100130 | B10: MACHADINHO D'OESTE-RO | C10: 6660
A11: 1100205 | B11: PORTO VELHO-RO | C11: 147840
A12: 1100262 | B12: RIO CRESPO-RO | C12: 6780
A13: 1100288 | B13: ROLIM DE MOURA-RO | C13: 4470
... A1465: 5300108 | B1465: BRASÍLIA-DF | C1465: 349721
A1466: Grand Total | C1466: 192857538
